<?xml version="1.0"?>
<robot name="mars_rover" xmlns:xacro="http://www.ros.org/wiki/xacro">

  <!-- Materials -->
  <material name="black"><color rgba="0.0 0.0 0.0 1.0"/></material>
  <material name="orange"><color rgba="1.0 0.4235 0.0392 1.0"/></material>
  <material name="green"><color rgba="0.0 0.8 0.0 1.0"/></material>

  <!-- Base Link -->
  <link name="base_link">
    <visual>
      <geometry><box size="0.3 0.3 0.1"/></geometry>
      <material name="orange"/>
    </visual>
    <collision>
      <geometry><box size="0.3 0.3 0.1"/></geometry>
    </collision>
    <inertial>
      <mass value="5.0"/>
      <origin xyz="0 0 0"/>
      <inertia ixx="0.1" ixy="0.0" ixz="0.0" iyy="0.1" iyz="0.0" izz="0.1"/>
    </inertial>
  </link>

  <gazebo reference="base_link">
    <material>Gazebo/Orange</material>
  </gazebo>

  <!-- Rear wheel macro (driven) -->
  <xacro:macro name="driven_wheel" params="prefix x y">
    <link name="${prefix}_wheel">
      <visual>
        <geometry><cylinder radius="0.05" length="0.02"/></geometry>
        <material name="black"/>
      </visual>
      <collision>
        <geometry><cylinder radius="0.05" length="0.02"/></geometry>
      </collision>
      <inertial>
        <mass value="0.2"/>
        <origin xyz="0 0 0"/>
        <inertia ixx="0.01" ixy="0.0" ixz="0.0" iyy="0.01" iyz="0.0" izz="0.01"/>
      </inertial>
    </link>

    <gazebo reference="${prefix}_wheel">
      <material>Gazebo/Black</material>
    </gazebo>

    <joint name="${prefix}_wheel_joint" type="continuous">
      <parent link="base_link"/>
      <child link="${prefix}_wheel"/>
      <origin xyz="${x} ${y} -0.05" rpy="1.5707 0 0"/>
      <axis xyz="0 0 -1"/>
      <dynamics damping="0.01" friction="0.0"/>
    </joint>
  </xacro:macro>

  <!-- Front wheel macro (dummy fixed) -->
  <xacro:macro name="dummy_wheel" params="prefix x y">
    <link name="${prefix}_wheel">
      <visual>
        <geometry><cylinder radius="0.05" length="0.02"/></geometry>
        <material name="black"/>
      </visual>
      <collision>
        <geometry><cylinder radius="0.05" length="0.02"/></geometry>
      </collision>
      <inertial>
        <mass value="0.2"/>
        <origin xyz="0 0 0"/>
        <inertia ixx="0.01" ixy="0.0" ixz="0.0" iyy="0.01" iyz="0.0" izz="0.01"/>
      </inertial>
    </link>

    <gazebo reference="${prefix}_wheel">
      <material>Gazebo/Black</material>
      <mu1>0.0</mu1>  
      <mu2>0.0</mu2>  
    </gazebo>

    <joint name="${prefix}_wheel_joint" type="fixed">
      <parent link="base_link"/>
      <child link="${prefix}_wheel"/>
      <origin xyz="${x} ${y} -0.05" rpy="1.5707 0 0"/>
    </joint>
  </xacro:macro>

  <!-- Front wheels (fixed) -->
  <xacro:dummy_wheel prefix="front_left" x="0.16" y="0.15"/>
  <xacro:dummy_wheel prefix="front_right" x="0.16" y="-0.15"/>

  <!-- Rear wheels (driven) -->
  <xacro:driven_wheel prefix="rear_left" x="-0.16" y="0.15"/>
  <xacro:driven_wheel prefix="rear_right" x="-0.16" y="-0.15"/>

  <!-- Gazebo Diff Drive Plugin -->
  <gazebo>
    <plugin name="diff_drive" filename="libgazebo_ros_diff_drive.so">
      <left_joint>rear_left_wheel_joint</left_joint>
      <right_joint>rear_right_wheel_joint</right_joint>

      <wheel_separation>0.32</wheel_separation>
      <wheel_diameter>0.1</wheel_diameter>

      <max_wheel_torque>200</max_wheel_torque>
      <max_wheel_acceleration>10.0</max_wheel_acceleration>

      <odometry_frame>odom</odometry_frame>
      <robot_base_frame>base_link</robot_base_frame>

      <publish_odom>true</publish_odom>
      <publish_odom_tf>true</publish_odom_tf>
      <publish_wheel_tf>true</publish_wheel_tf>
    </plugin>
  </gazebo>

  <!-- Camera -->
  <link name="camera_link">
    <visual>
      <geometry><box size="0.05 0.05 0.05"/></geometry>
      <material name="green"/>
    </visual>
    <collision>
      <geometry><box size="0.05 0.05 0.05"/></geometry>
    </collision>
    <inertial>
      <mass value="0.1"/>
      <origin xyz="0 0 0"/>
      <inertia ixx="0.001" ixy="0.0" ixz="0.0" iyy="0.001" iyz="0.0" izz="0.001"/>
    </inertial>
  </link>

  <joint name="camera_joint" type="fixed">
    <parent link="base_link"/>
    <child link="camera_link"/>
    <origin xyz="0.175 0 0.07" rpy="0 0.3 0"/>
  </joint>

  <gazebo reference="camera_link">
    <material>Gazebo/Green</material>
    <sensor name="camera" type="camera">
      <pose>0 0 0 0 0 0</pose>
      <always_on>true</always_on>
      <update_rate>30.0</update_rate>
      <camera>
        <horizontal_fov>1.3962634</horizontal_fov>
        <image>
          <width>640</width>
          <height>480</height>
          <format>R8G8B8</format>
        </image>
        <clip>
          <near>0.1</near>
          <far>2</far>
        </clip>
      </camera>
      <plugin name="gazebo_ros_camera" filename="libgazebo_ros_camera.so">
        <cameraName>camera</cameraName>
        <imageTopicName>image_raw</imageTopicName>
        <cameraInfoTopicName>camera_info</cameraInfoTopicName>
        <frameName>camera_link</frameName>
      </plugin>
    </sensor>
  </gazebo>


    <!-- LiDAR -->
  <link name="lidar_link">
    <visual>
      <geometry><cylinder radius="0.03" length="0.02"/></geometry>
      <material name="green"/>
    </visual>
    <collision>
      <geometry><cylinder radius="0.03" length="0.02"/></geometry>
    </collision>
    <inertial>
      <mass value="0.1"/>
      <origin xyz="0 0 0"/>
      <inertia ixx="0.001" ixy="0.0" ixz="0.0" iyy="0.001" iyz="0.0" izz="0.001"/>
    </inertial>
  </link>

  <joint name="lidar_joint" type="fixed">
    <parent link="base_link"/>
    <child link="lidar_link"/>
    <origin xyz="0.0 0 0.15" rpy="0 0 0"/>
  </joint>

  <gazebo reference="lidar_link">
    <sensor name="lidar_sensor" type="ray">
      <pose>0 0 0 0 0 0</pose>
      <visualize>true</visualize>
      <update_rate>10.0</update_rate>
      <ray>
        <scan>
          <horizontal>
            <samples>720</samples>
            <resolution>1</resolution>
            <min_angle>-3.1415</min_angle>
            <max_angle>3.1415</max_angle>
          </horizontal>
        </scan>
        <range>
          <min>0.12</min>
          <max>8.0</max>
          <resolution>0.01</resolution>
        </range>
        <noise>
          <type>gaussian</type>
          <mean>0.0</mean>
          <stddev>0.01</stddev>
        </noise>
      </ray>
      
<plugin name="gazebo_ros_laser_controller" filename="libgazebo_ros_ray_sensor.so">
  <ros>
    <remapping>scan:=/scan</remapping>
  </ros>
  <frameName>lidar_link</frameName>
  <output_type>sensor_msgs/LaserScan</output_type>  
</plugin>

    </sensor>
  </gazebo>


</robot>
